Workbook

Sheet Customer Names
A1: Customer ID | B1: First name | C1: Title | D1: Last name
A2: Id1 | B2: Hawks | C2: Ms | D2: Kelly
A3: Id2 | B3: Lehner | C3: Mr | D3: Matthew D
A4: Id3 | B4: Lu | C4: Mr | D4: Phil
A5: Id4 | B5: Osborne | C5: Ms | D5: Kelsey
A6: Id5 | B6: Kadala | C6: Ms | D6: Kristyn
A7: Id6 | B7: Baker | C7: Mr | D7: Russell B
A8: Id7 | B8: Macpherson | C8: Mr | D8: Scott
A9: Id8 | B9: Hallman | C9: Mr | D9: Stephen
A10: Id9 | B10: Moran | C10: Mr | D10: Patrick R
A11: Id10 | B11: Benner | C11: Ms | D11: Brooke N
A12: Id11 | B12: Fierro Vargas | C12: Ms | D12: Paola Andrea
... A2336: Id2335 | B2336: German | C2336: Mr | D2336: Aaron K
A2337: =COUNTBLANK(A2:A2336) -> 0 | B2337: =COUNTBLANK(B2:B2336) -> 0 | C2337: =COUNTBLANK(C2:C2336) -> 0 | D2337: =COUNTBLANK((D2:D2336)) -> 0

Sheet Medical Examinations
A1: Customer ID | B1: BMI | C1: HBA1C | D1: Heart Issues | E1: Any Transplants | F1: Cancer history | G1: NumberOfMajorSurgeries | H1: Smoker | I1: Weight Status | J1: Diabetes Status
A2: Id1 | B2: 47.41 | C2: 7.47 | D2: No | E2: No | F2: No | G2: 0 | H2: Yes | I2: =VLOOKUP(B2,$L$10:$M$13,2,TRUE) -> Obesity | J2: =VLOOKUP(C2,$K$19:$L$21,2,TRUE) -> Diabetes
A3: Id2 | B3: 30.36 | C3: 5.77 | D3: No | E3: No | F3: No | G3: 0 | H3: Yes | I3: =VLOOKUP(B3,$L$10:$M$13,2,TRUE) -> Obesity | J3: =VLOOKUP(C3,$K$19:$L$21,2,TRUE) -> Prediabetes
A4: Id3 | B4: 34.485 | C4: 11.87 | D4: Yes | E4: No | F4: No | G4: 2 | H4: Yes | I4: =VLOOKUP(B4,$L$10:$M$13,2,TRUE) -> Obesity | J4: =VLOOKUP(C4,$K$19:$L$21,2,TRUE) -> Diabetes
A5: Id4 | B5: 38.095 | C5: 6.05 | D5: No | E5: No | F5: No | G5: 0 | H5: Yes | I5: =VLOOKUP(B5,$L$10:$M$13,2,TRUE) -> Obesity | J5: =VLOOKUP(C5,$K$19:$L$21,2,TRUE) -> Prediabetes
A6: Id5 | B6: 35.53 | C6: 5.45 | D6: No | E6: No | F6: No | G6: 0 | H6: Yes | I6: =VLOOKUP(B6,$L$10:$M$13,2,TRUE) -> Obesity | J6: =VLOOKUP(C6,$K$19:$L$21,2,TRUE) -> Normal
A7: Id6 | B7: 32.8 | C7: 6.59 | D7: No | E7: No | F7: No | G7: 0 | H7: Yes | I7: =VLOOKUP(B7,$L$10:$M$13,2,TRUE) -> Obesity | J7: =VLOOKUP(C7,$K$19:$L$21,2,TRUE) -> Diabetes
A8: Id7 | B8: 36.4 | C8: 6.07 | D8: No | E8: No | F8: No | G8: 0 | H8: Yes | I8: =VLOOKUP(B8,$L$10:$M$13,2,TRUE) -> Obesity | J8: =VLOOKUP(C8,$K$19:$L$21,2,TRUE) -> Prediabetes
A9: Id8 | B9: 36.96 | C9: 7.93 | D9: No | E9: No | F9: No | G9: 3 | H9: Yes | I9: =VLOOKUP(B9,$L$10:$M$13,2,TRUE) -> Obesity | J9: =VLOOKUP(C9,$K$19:$L$21,2,TRUE) -> Diabetes | L9: BMI | M9: Weight Status
A10: Id9 | B10: 41.14 | C10: 9.58 | D10: Yes | E10: No | F10: Yes | G10: 1 | H10: Yes | I10: =VLOOKUP(B10,$L$10:$M$13,2,TRUE) -> Obesity | J10: =VLOOKUP(C10,$K$19:$L$21,2,TRUE) -> Diabetes | L10: 0 | M10: Underweight
A11: Id10 | B11: 38.06 | C11: 10.79 | D11: No | E11: No | F11: No | G11: 0 | H11: Yes | I11: =VLOOKUP(B11,$L$10:$M$13,2,TRUE) -> Obesity | J11: =VLOOKUP(C11,$K$19:$L$21,2,TRUE) -> Diabetes | L11: 18.5 | M11: Normal Weight
A12: Id11 | B12: 37.7 | C12: 5.96 | D12: Yes | E12: No | F12: No | G12: 2 | H12: Yes | I12: =VLOOKUP(B12,$L$10:$M$13,2,TRUE) -> Obesity | J12: =VLOOKUP(C12,$K$19:$L$21,2,TRUE) -> Prediabetes | L12: 25 | M12: Overweight
A13: Id12 | B13: 42.13 | C13: 11.9 | D13: No | E13: No | F13: No | G13: 0 | H13: Yes | I13: =VLOOKUP(B13,$L$10:$M$13,2,TRUE) -> Obesity | J13: =VLOOKUP(C13,$K$19:$L$21,2,TRUE) -> Diabetes | L13: 30 | M13: Obesity
A14: Id13 | B14: 40.92 | C14: 8.41 | D14: No | E14: No | F14: No | G14: 0 | H14: Yes | I14: =VLOOKUP(B14,$L$10:$M$13,2,TRUE) -> Obesity | J14: =VLOOKUP(C14,$K$19:$L$21,2,TRUE) -> Diabetes
A15: Id14 | B15: 40.565 | C15: 7.02 | D15: No | E15: No | F15: No | G15: 0 | H15: Yes | I15: =VLOOKUP(B15,$L$10:$M$13,2,TRUE) -> Obesity | J15: =VLOOKUP(C15,$K$19:$L$21,2,TRUE) -> Diabetes
A16: Id15 | B16: 36.385 | C16: 7.59 | D16: Yes | E16: No | F16: No | G16: 2 | H16: Yes | I16: =VLOOKUP(B16,$L$10:$M$13,2,TRUE) -> Obesity | J16: =VLOOKUP(C16,$K$19:$L$21,2,TRUE) -> Diabetes
A17: Id16 | B17: 39.9 | C17: 11.32 | D17: No | E17: No | F17: No | G17: 0 | H17: Yes | I17: =VLOOKUP(B17,$L$10:$M$13,2,TRUE) -> Obesity | J17: =VLOOKUP(C17,$K$19:$L$21,2,TRUE) -> Diabetes
A18: Id17 | B18: 33.8 | C18: 7.67 | D18: No | E18: No | F18: No | G18: 3 | H18: Yes | I18: =VLOOKUP(B18,$L$10:$M$13,2,TRUE) -> Obesity | J18: =VLOOKUP(C18,$K$19:$L$21,2,TRUE) -> Diabetes | K18: HbA1C | L18: Diabetes Status
A19: Id18 | B19: 36.765 | C19: 7.29 | D19: Yes | E19: No | F19: Yes | G19: 1 | H19: Yes | I19: =VLOOKUP(B19,$L$10:$M$13,2,TRUE) -> Obesity | J19: =VLOOKUP(C19,$K$19:$L$21,2,TRUE) -> Diabetes | K19: 0 | L19: Normal
A20: Id19 | B20: 36.955 | C20: 4.72 | D20: Yes | E20: No | F20: No | G20: 1 | H20: Yes | I20: =VLOOKUP(B20,$L$10:$M$13,2,TRUE) -> Obesity | J20: =VLOOKUP(C20,$K$19:$L$21,2,TRUE) -> Normal | K20: 5.7 | L20: Prediabetes
A21: Id20 | B21: 42.9 | C21: 11.41 | D21: No | E21: No | F21: No | G21: 0 | H21: Yes | I21: =VLOOKUP(B21,$L$10:$M$13,2,TRUE) -> Obesity | J21: =VLOOKUP(C21,$K$19:$L$21,2,TRUE) -> Diabetes | K21: 6.5 | L21: Diabetes
A22: Id21 | B22: 36.3 | C22: 11.5 | D22: Yes | E22: No | F22: No | G22: 2 | H22: Yes | I22: =VLOOKUP(B22,$L$10:$M$13,2,TRUE) -> Obesity | J22: =VLOOKUP(C22,$K$19:$L$21,2,TRUE) -> Diabetes
A23: Id22 | B23: 32.2 | C23: 6.22 | D23: Yes | E23: No | F23: No | G23: 2 | H23: Yes | I23: =VLOOKUP(B23,$L$10:$M$13,2,TRUE) -> Obesity | J23: =VLOOKUP(C23,$K$19:$L$21,2,TRUE) -> Prediabetes
A24: Id23 | B24: 31.3 | C24: 11.38 | D24: No | E24: No | F24: No | G24: 3 | H24: Yes | I24: =VLOOKUP(B24,$L$10:$M$13,2,TRUE) -> Obesity | J24: =VLOOKUP(C24,$K$19:$L$21,2,TRUE) -> Diabetes
A25: Id24 | B25: 41.8 | C25: 7.89 | D25: Yes | E25: No | F25: No | G25: 2 | H25: Yes | I25: =VLOOKUP(B25,$L$10:$M$13,2,TRUE) -> Obesity | J25: =VLOOKUP(C25,$K$19:$L$21,2,TRUE) -> Diabetes
A26: Id25 | B26: 35.09 | C26: 4.38 | D26: Yes | E26: No | F26: No | G26: 2 | H26: Yes | I26: =VLOOKUP(B26,$L$10:$M$13,2,TRUE) -> Obesity | J26: =VLOOKUP(C26,$K$19:$L$21,2,TRUE) -> Normal
A27: Id26 | B27: 33.88 | C27: 7.01 | D27: No | E27: No | F27: No | G27: 3 | H27: Yes | I27: =VLOOKUP(B27,$L$10:$M$13,2,TRUE) -> Obesity | J27: =VLOOKUP(C27,$K$19:$L$21,2,TRUE) -> Diabetes
A28: Id27 | B28: 30.875 | C28: 11.88 | D28: No | E28: No | F28: No | G28: 0 | H28: Yes | I28: =VLOOKUP(B28,$L$10:$M$13,2,TRUE) -> Obesity | J28: =VLOOKUP(C28,$K$19:$L$21,2,TRUE) -> Diabetes
A29: Id28 | B29: 36.86 | C29: 5.19 | D29: Yes | E29: No | F29: Yes | G29: 1 | H29: Yes | I29: =VLOOKUP(B29,$L$10:$M$13,2,TRUE) -> Obesity | J29: =VLOOKUP(C29,$K$19:$L$21,2,TRUE) -> Normal
A30: Id29 | B30: 35.86 | C30: 6.74 | D30: Yes | E30: No | F30: No | G30: 2 | H30: Yes | I30: =VLOOKUP(B30,$L$10:$M$13,2,TRUE) -> Obesity | J30: =VLOOKUP(C30,$K$19:$L$21,2,TRUE) -> Diabetes
A31: Id30 | B31: 37.05 | C31: 8.44 | D31: No | E31: No | F31: No | G31: 0 | H31: Yes | I31: =VLOOKUP(B31,$L$10:$M$13,2,TRUE) -> Obesity | J31: =VLOOKUP(C31,$K$19:$L$21,2,TRUE) -> Diabetes
A32: Id31 | B32: 43.89 | C32: 8.71 | D32: No | E32: No | F32: No | G32: 0 | H32: Yes | I32: =VLOOKUP(B32,$L$10:$M$13,2,TRUE) -> Obesity | J32: =VLOOKUP(C32,$K$19:$L$21,2,TRUE) -> Diabetes
A33: Id32 | B33: 42.35 | C33: 5.08 | D33: Yes | E33: No | F33: No | G33: 0 | H33: Yes | I33: =VLOOKUP(B33,$L$10:$M$13,2,TRUE) -> Obesity | J33: =VLOOKUP(C33,$K$19:$L$21,2,TRUE) -> Normal
... A560: Id559 | B560: 28.88 | C560: 5.35 | D560: No | E560: No | F560: Yes | G560: 1 | H560: Yes | I560: =VLOOKUP(B560,$L$10:$M$13,2,TRUE) -> Overweight | J560: =VLOOKUP(C560,$K$19:$L$21,2,TRUE) -> Normal
A561: Id560 | B561: 23.98 | C561: 4.9 | D561: No | E561: No | F561: No | G561: 0 | H561: #REF! | I561: =VLOOKUP(B561,$L$10:$M$13,2,TRUE) -> Normal Weight | J561: =VLOOKUP(C561,$K$19:$L$21,2,TRUE) -> Normal
A562: Id561 | B562: 23.65 | C562: 4.5 | D562: No | E562: No | F562: No | G562: 0 | H562: No | I562: =VLOOKUP(B562,$L$10:$M$13,2,TRUE) -> Normal Weight | J562: =VLOOKUP(C562,$K$19:$L$21,2,TRUE) -> Normal
A563: Id562 | B563: 49.09 | C563: 8.38 | D563: Yes | E563: No | F563: No | G563: 2 | H563: No | I563: =VLOOKUP(B563,$L$10:$M$13,2,TRUE) -> Obesity | J563: =VLOOKUP(C563,$K$19:$L$21,2,TRUE) -> Diabetes
A564: Id563 | B564: 28.025 | C564: 7.03 | D564: No | E564: No | F564: No | G564: 0 | H564: Yes | I564: =VLOOKUP(B564,$L$10:$M$13,2,TRUE) -> Overweight | J564: =VLOOKUP(C564,$K$19:$L$21,2,TRUE) -> Diabetes
A565: Id564 | B565: 43.32 | C565: 8.75 | D565: Yes | E565: No | F565: Yes | G565: 1 | H565: No | I565: =VLOOKUP(B565,$L$10:$M$13,2,TRUE) -> Obesity | J565: =VLOOKUP(C565,$K$19:$L$21,2,TRUE) -> Diabetes
A566: Id565 | B566: 45.92 | C566: 9.51 | D566: No | E566: No | F566: No | G566: 0 | H566: No | I566: =VLOOKUP(B566,$L$10:$M$13,2,TRUE) -> Obesity | J566: =VLOOKUP(C566,$K$19:$L$21,2,TRUE) -> Diabetes
...

Sheet Hospitalisation Details
A1: Customer ID | B1: year | C1: month | D1: date | E1: Date Of Birth | F1: children | G1: charges | H1: Hospital tier | I1: City tier | J1: State ID | K1: Age
A2: Id2335 | B2: 1992 | C2: Jul | D2: 9 | E2: =CONCATENATE(D2," ",C2," ",B2) -> 9 Jul 1992 | F2: 0 | G2: 563.84 | H2: tier - 2 | I2: tier - 3 | J2: R1013 | K2: =DATEDIF(E2,$L$2,"y") -> 32 | L2: 45775
A3: Id2334 | B3: 1992 | C3: Nov | D3: 30 | E3: =CONCATENATE(D3," ",C3," ",B3) -> 30 Nov 1992 | F3: 0 | G3: 570.62 | H3: tier - 2 | I3: tier - 1 | J3: R1013 | K3: =DATEDIF(E3,$L$2,"y") -> 32
A4: Id2333 | B4: 1993 | C4: Jun | D4: 30 | E4: =CONCATENATE(D4," ",C4," ",B4) -> 30 Jun 1993 | F4: 0 | G4: 600 | H4: tier - 2 | I4: tier - 1 | J4: R1013 | K4: =DATEDIF(E4,$L$2,"y") -> 31
A5: Id2332 | B5: 1992 | C5: Sep | D5: 13 | E5: =CONCATENATE(D5," ",C5," ",B5) -> 13 Sep 1992 | F5: 0 | G5: 604.54 | H5: tier - 3 | I5: tier - 3 | J5: R1013 | K5: =DATEDIF(E5,$L$2,"y") -> 32
A6: Id2331 | B6: 1998 | C6: Jul | D6: 27 | E6: =CONCATENATE(D6," ",C6," ",B6) -> 27 Jul 1998 | F6: 0 | G6: 637.26 | H6: tier - 3 | I6: tier - 3 | J6: R1013 | K6: =DATEDIF(E6,$L$2,"y") -> 26
A7: Id2330 | B7: 2001 | C7: Nov | D7: 20 | E7: =CONCATENATE(D7," ",C7," ",B7) -> 20 Nov 2001 | F7: 0 | G7: 646.14 | H7: tier - 3 | I7: tier - 3 | J7: R1012 | K7: =DATEDIF(E7,$L$2,"y") -> 23
A8: Id2329 | B8: 1993 | C8: Jun | D8: 1 | E8: =CONCATENATE(D8," ",C8," ",B8) -> 1 Jun 1993 | F8: 0 | G8: 650 | H8: tier - 3 | I8: tier - 3 | J8: R1013 | K8: =DATEDIF(E8,$L$2,"y") -> 31
A9: Id2328 | B9: 1995 | C9: Jul | D9: 4 | E9: =CONCATENATE(D9," ",C9," ",B9) -> 4 Jul 1995 | F9: 0 | G9: 650 | H9: tier - 3 | I9: tier - 3 | J9: R1013 | K9: =DATEDIF(E9,$L$2,"y") -> 29
A10: Id2327 | B10: 2002 | C10: Nov | D10: 29 | E10: =CONCATENATE(D10," ",C10," ",B10) -> 29 Nov 2002 | F10: 0 | G10: 668 | H10: tier - 3 | I10: tier - 2 | J10: R1012 | K10: =DATEDIF(E10,$L$2,"y") -> 22
A11: Id2326 | B11: 1997 | C11: Nov | D11: 9 | E11: =CONCATENATE(D11," ",C11," ",B11) -> 9 Nov 1997 | F11: 0 | G11: 670 | H11: tier - 3 | I11: tier - 3 | J11: R1013 | K11: =DATEDIF(E11,$L$2,"y") -> 27
A12: Id2325 | B12: 2001 | C12: Sep | D12: 12 | E12: =CONCATENATE(D12," ",C12," ",B12) -> 12 Sep 2001 | F12: 0 | G12: 687.54 | H12: tier - 3 | I12: tier - 2 | J12: R1013 | K12: =DATEDIF(E12,$L$2,"y") -> 23
A13: Id2324 | B13: 1999 | C13: Dec | D13: 26 | E13: =CONCATENATE(D13," ",C13," ",B13) -> 26 Dec 1999 | F13: 0 | G13: 700 | H13: UNKNOWN | I13: tier - 3 | J13: R1013 | K13: =DATEDIF(E13,$L$2,"y") -> 25
A14: Id2323 | B14: 1999 | C14: Dec | D14: 14 | E14: =CONCATENATE(D14," ",C14," ",B14) -> 14 Dec 1999 | F14: 0 | G14: 722.99 | H14: tier - 3 | I14: tier - 1 | J14: R1013 | K14: =DATEDIF(E14,$L$2,"y") -> 25
... A1050: Id1290 | B1050: 1977 | C1050: Jul | D1050: 26 | E1050: =CONCATENATE(D1050," ",C1050," ",B1050) -> 26 Jul 1977 | F1050: 2 | G1050: 8527.53 | H1050: tier - 2 | I1050: tier - 2 | J1050: R1013 | K1050: =DATEDIF(E1050,$L$2,"y") -> 47
A1051: Id1289 | B1051: Sep | C1051: Jul | D1051: 24 | E1051: =CONCATENATE(D1051," ",C1051," ",B1051) -> 24 Jul Sep | F1051: 0 | G1051: 8534.67 | H1051: tier - 2 | I1051: tier - 3 | J1051: R1024 | K1051: =DATEDIF(E1051,$L$2,"y") -> #VALUE!
A1052: Id1288 | B1052: 1981 | C1052: Dec | D1052: 27 | E1052: =CONCATENATE(D1052," ",C1052," ",B1052) -> 27 Dec 1981 | F1052: 3 | G1052: 8538.29 | H1052: tier - 2 | I1052: tier - 3 | J1052: R1024 | K1052: =DATEDIF(E1052,$L$2,"y") -> 43
A1053: Id1287 | B1053: 1975 | C1053: Nov | D1053: 6 | E1053: =CONCATENATE(D1053," ",C1053," ",B1053) -> 6 Nov 1975 | F1053: 1 | G1053: 8539.67 | H1053: tier - 2 | I1053: tier - 3 | J1053: R1011 | K1053: =DATEDIF(E1053,$L$2,"y") -> 49
A1054: Id1286 | B1054: Sep | C1054: Dec | D1054: 12 | E1054: =CONCATENATE(D1054," ",C1054," ",B1054) -> 12 Dec Sep | F1054: 1 | G1054: 8547.69 | H1054: tier - 2 | I1054: tier - 1 | J1054: R1013 | K1054: =DATEDIF(E1054,$L$2,"y") -> #VALUE!
A1055: Id1285 | B1055: 1975 | C1055: Aug | D1055: 6 | E1055: =CONCATENATE(D1055," ",C1055," ",B1055) -> 6 Aug 1975 | F1055: 1 | G1055: 8551.35 | H1055: tier - 2 | I1055: tier - 2 | J1055: R1011 | K1055: =DATEDIF(E1055,$L$2,"y") -> 49
A1056: Id1284 | B1056: 1975 | C1056: Aug | D1056: 21 | E1056: =CONCATENATE(D1056," ",C1056," ",B1056) -> 21 Aug 1975 | F1056: 1 | G1056: 8556.91 | H1056: tier - 2 | I1056: tier - 1 | J1056: R1011 | K1056: =DATEDIF(E1056,$L$2,"y") -> 49
A1057: Id1283 | B1057: 1988 | C1057: Sep | D1057: 21 | E1057: =CONCATENATE(D1057," ",C1057," ",B1057) -> 21 Sep 1988 | F1057: 3 | G1057: 8567.25 | H1057: tier - 2 | I1057: tier - 1 | J1057: R1012 | K1057: =DATEDIF(E1057,$L$2,"y") -> 36
A1058: Id1282 | B1058: 1975 | C1058: Sep | D1058: 26 | E1058: =CONCATENATE(D1058," ",C1058," ",B1058) -> 26 Sep 1975 | F1058: 1 | G1058: 8569.86 | H1058: tier - 2 | I1058: tier - 3 | J1058: R1013 | K1058: =DATEDIF(E1058,$L$2,"y") -> 49
A1059: Id1281 | B1059: 1982 | C1059: Dec | D1059: 6 | E1059: =CONCATENATE(D1059," ",C1059," ",B1059) -> 6 Dec 1982 | F1059: 3 | G1059: 8572.04 | H1059: tier - 2 | I1059: tier - 2 | J1059: R1021 | K1059: =DATEDIF(E1059,$L$2,"y") -> 42
A1060: Id1280 | B1060: 1987 | C1060: Nov | D1060: 11 | E1060: =CONCATENATE(D1060," ",C1060," ",B1060) -> 11 Nov 1987 | F1060: 3 | G1060: 8573.3 | H1060: tier - 2 | I1060: tier - 2 | J1060: R1021 | K1060: =DATEDIF(E1060,$L$2,"y") -> 37
A1061: Id1279 | B1061: 1983 | C1061: Dec | D1061: 30 | E1061: =CONCATENATE(D1061," ",C1061," ",B1061) -> 30 Dec 1983 | F1061: 5 | G1061: 8582.3 | H1061: tier - 2 | I1061: tier - 1 | J1061: R1013 | K1061: =DATEDIF(E1061,$L$2,"y") -> 41
A1062: Id1278 | B1062: 1983 | C1062: Jul | D1062: 25 | E1062: =CONCATENATE(D1062," ",C1062," ",B1062) -> 25 Jul 1983 | F1062: 5 | G1062: 8596.83 | H1062: tier - 2 | I1062: tier - 3 | J1062: R1013 | K1062: =DATEDIF(E1062,$L$2,"y") -> 41
A1063: Id1277 | B1063: 1973 | C1063: Jul | D1063: 11 | E1063: =CONCATENATE(D1063," ",C1063," ",B1063) -> 11 Jul 1973 | F1063: 0 | G1063: 8601.33 | H1063: tier - 2 | I1063: tier - 1 | J1063: R1013 | K1063: =DATEDIF(E1063,$L$2,"y") -> 51
A1064: Id1276 | B1064: 1977 | C1064: Sep | D1064: 24 | E1064: =CONCATENATE(D1064," ",C1064," ",B1064) -> 24 Sep 1977 | F1064: 2 | G1064: 8603.82 | H1064: tier - 2 | I1064: tier - 1 | J1064: R1019 | K1064: =DATEDIF(E1064,$L$2,"y") -> 47
A1065: Id1275 | B1065: 1977 | C1065: Nov | D1065: 12 | E1065: =CONCATENATE(D1065," ",C1065," ",B1065) -> 12 Nov 1977 | F1065: 2 | G1065: 8604.48 | H1065: tier - 3 | I1065: tier - 2 | J1065: R1016 | K1065: =DATEDIF(E1065,$L$2,"y") -> 47
A1066: Id1274 | B1066: 1977 | C1066: Oct | D1066: 15 | E1066: =CONCATENATE(D1066," ",C1066," ",B1066) -> 15 Oct 1977 | F1066: 3 | G1066: 8605.36 | H1066: tier - 2 | I1066: tier - 2 | J1066: R1013 | K1066: =DATEDIF(E1066,$L$2,"y") -> 47
... A2159: Id184 | B2159: 1965 | C2159: Dec | D2159: 28 | E2159: =CONCATENATE(D2159," ",C2159," ",B2159) -> 28 Dec 1965 | F2159: 0 | G2159: 36795.29 | H2159: tier - 2 | I2159: tier - 1 | J2159: R1011 | K2159: =DATEDIF(E2159,$L$2,"y") -> 59
B2160: 1992 | C2160: Oct | D2160: 6 | E2160: =CONCATENATE(D2160," ",C2160," ",B2160) -> 6 Oct 1992 | F2160: 0 | G2160: 36837.47 | H2160: tier - 1 | I2160: tier - 2 | J2160: R1011 | K2160: =DATEDIF(E2160,$L$2,"y") -> 32
A2161: Id183 | B2161: 1992 | C2161: Jul | D2161: 4 | E2161: =CONCATENATE(D2161," ",C2161," ",B2161) -> 4 Jul 1992 | F2161: 0 | G2161: 36837.47 | H2161: tier - 2 | I2161: tier - 3 | J2161: R1011 | K2161: =DATEDIF(E2161,$L$2,"y") -> 32
A2162: Id182 | B2162: 1972 | C2162: Dec | D2162: 5 | E2162: =CONCATENATE(D2162," ",C2162," ",B2162) -> 5 Dec 1972 | F2162: 0 | G2162: 36889.99 | H2162: tier - 1 | I2162: tier - 3 | J2162: R1011 | K2162: =DATEDIF(E2162,$L$2,"y") -> 52
A2163: Id181 | B2163: 2003 | C2163: Jun | D2163: 21 | E2163: =CONCATENATE(D2163," ",C2163," ",B2163) -> 21 Jun 2003 | F2163: 0 | G2163: 36898.73 | H2163: tier - 2 | I2163: tier - 1 | J2163: R1012 | K2163: =DATEDIF(E2163,$L$2,"y") -> 21
A2164: Id180 | B2164: 1963 | C2164: Jul | D2164: 24 | E2164: =CONCATENATE(D2164," ",C2164," ",B2164) -> 24 Jul 1963 | F2164: 2 | G2164: 36910.61 | H2164: tier - 2 | I2164: tier - 2 | J2164: R1011 | K2164: =DATEDIF(E2164,$L$2,"y") -> 61
A2165: Id179 | B2165: 1991 | C2165: Jun | D2165: 10 | E2165: =CONCATENATE(D2165," ",C2165," ",B2165) -> 10 Jun 1991 | F2165: 3 | G2165: 36911.99 | H2165: tier - 2 | I2165: tier - 2 | J2165: R1011 | K2165: =DATEDIF(E2165,$L$2,"y") -> 33
A2166: Id178 | B2166: 1968 | C2166: Oct | D2166: 22 | E2166: =CONCATENATE(D2166," ",C2166," ",B2166) -> 22 Oct 1968 | F2166: 0 | G2166: 36922.61 | H2166: tier - 2 | I2166: tier - 1 | J2166: R1011 | K2166: =DATEDIF(E2166,$L$2,"y") -> 56
A2167: Id177 | B2167: 1977 | C2167: Aug | D2167: 13 | E2167: =CONCATENATE(D2167," ",C2167," ",B2167) -> 13 Aug 1977 | F2167: 2 | G2167: 36935.64 | H2167: tier - 2 | I2167: tier - 1 | J2167: R1011 | K2167: =DATEDIF(E2167,$L$2,"y") -> 47
...

Sheet Analysis
A3: Count of Cancer history | B3: Column Labels
A4: Row Labels | B4: No | C4: Yes | D4: Grand Total
A5: No | B5: 1531 | C5: 411 | D5: 1942
A6: Yes | B6: 314 | C6: 77 | D6: 391
A7: Grand Total | B7: 1845 | C7: 488 | D7: 2333
A18: Row Labels | B18: Sum of Number Of Major Surgeries | C18: Average of HBA1C
A19: No | B19: 1417 | C19: 6.6704427
A20: Yes | B20: 162 | C20: 5.1876389
A21: Grand Total | B21: 1579 | C21: 6.5789979
A29: Sum of charges | B29: Column Labels
A30: Row Labels | B30: Diabetes | C30: Normal | D30: Prediabetes | E30: Grand Total
A31: Normal Weight | B31: 1730218.2 | C31: 1714717.2 | D31: 860354.71 | E31: 4305290.1
A32: Obesity | B32: 8184059.1 | C32: 8520712.9 | D32: 3638874.8 | E32: 20343647
A33: Overweight | B33: 2240235.2 | C33: 2437209 | D33: 1051697.5 | E33: 5729141.8
A34: Underweight | B34: 483792.72 | C34: 566702.46 | D34: 163784.7 | E34: 1214279.9
A35: Grand Total | B35: 12638305 | C35: 13239342 | D35: 5714711.8 | E35: 31592359
A41: Average Charges by Hospital Tier and State | B41: Column Labels
A42: Row Labels | B42: tier - 1 | C42: tier - 2 | D42: tier - 3 | E42: UNKNOWN | F42: (blank) | G42: Grand Total
A43: R1026 | B43: 93548.99 | C43: 500623.53 | D43: 454980.85 | G43: 1049153.4
A44: R1025 | C44: 130834.7 | D44: 220716.59 | G44: 351551.29
A45: R1024 | B45: 458250.62 | C45: 1119178.1 | D45: 480995.24 | G45: 2058423.9
A46: R1023 | B46: 73047.03 | C46: 322970.27 | D46: 127856.37 | G46: 523873.67
A47: R1022 | C47: 90918.24 | D47: 58189.06 | G47: 149107.3
A48: R1021 | C48: 360404.4 | D48: 264932.07 | G48: 625336.47
A49: R1020 | C49: 20281.63 | D49: 35149.36 | G49: 55430.99
A50: R1019 | B50: 138108.05 | C50: 89283.92 | D50: 127069.76 | G50: 354461.73
A51: R1018 | B51: 33475.82 | C51: 60837.32 | D51: 25141.94 | G51: 119455.08
A52: R1017 | B52: 238494.17 | C52: 181849.95 | D52: 112675.76 | G52: 533019.88
A53: R1016 | B53: 318948.93 | C53: 192911.56 | D53: 357852.37 | G53: 869712.86
A54: R1015 | B54: 43047.04 | C54: 94053.26 | D54: 30283.02 | G54: 167383.32
A55: R1014 | B55: 138918.6 | C55: 2395.17 | D55: 33900.97 | G55: 175214.74
A56: R1013 | B56: 2098982.8 | C56: 3164031.6 | D56: 1171428.7 | E56: 700 | G56: 6435143.2
A57: R1012 | B57: 1645021.8 | C57: 3503320.7 | D57: 1761130 | G57: 6909472.5
A58: R1011 | B58: 3837439.4 | C58: 6041135.3 | D58: 1295050.7 | G58: 11173625
A59: 0
A60: Grand Total | B60: 9117283.3 | C60: 15875030 | D60: 6557352.6 | E60: 700 | G60: 31550366
A61: Row Labels | B61: Average of BMI | C61: Average of HBA1C
A62: 20-30 | B62: 30.287461 | C62: 5.5390125
A63: 31-40 | B63: 31.064765 | C63: 5.5534082
A64: 41-50 | B64: 31.073376 | C64: 7.0045866
...

Sheet Healthcare
A1: Customer ID | B1: year | C1: month | D1: date | E1: Date Of Birth | G1: charges | H1: Hospital tier | I1: City tier | J1: State ID | K1: Age Date | L1: First name | M1: Age | N1: BMI | O1: HBA1C | P1: Heart Issues | Q1: Any Transplants | R1: Number Of Major Surgeries | S1: Cancer history | T1: Smoker | U1: Weight Status | V1: Diabetes Status
A2: Id2335 | B2: 1992 | C2: Jul | D2: 9 | E2: =CONCATENATE(D2," ",C2," ",B2) -> 9 Jul 1992 | F2: =IF(M2<=30,"20-30",IF(M2<=40,"31-40",IF(M2<=50,"41-50","51+"))) -> 31-40 | G2: 563.84 | H2: tier - 2 | I2: tier - 3 | J2: R1013 | K2: 45775 | L2: =VLOOKUP(A2,'Customer Names'!$A$2:$B$2336,2,FALSE) -> German | M2: =DATEDIF(E2,$K$2,"y") -> 32 | N2: =VLOOKUP(A2,'Medical Examinations'!$A$2:$B$2336,2,FALSE) -> 17.58 | O2: =VLOOKUP(A2,'Medical Examinations'!$A$1:$J$2336,3,FALSE) -> 4.51 | P2: =VLOOKUP(A2,'Medical Examinations'!$A$1:$J$2336,4,FALSE) -> No | Q2: =VLOOKUP(A2,'Medical Examinations'!$A$1:$J$2336,5,FALSE) -> No | R2: =VLOOKUP(A2,'Medical Examinations'!$A$1:$J$2336,7,FALSE) -> 1 | S2: =VLOOKUP(A2,'Medical Examinations'!$A$1:$J$2336,6,FALSE) -> No | T2: =VLOOKUP(A2,'Medical Examinations'!$A$1:$J$2336,8,FALSE) -> No | U2: =VLOOKUP(A2,'Medical Examinations'!$A$1:$J$2336,9,FALSE) -> Underweight | V2: =VLOOKUP(A2,'Medical Examinations'!$A$1:$J$2336,10,FALSE) -> Normal
A3: Id2334 | B3: 1992 | C3: Nov | D3: 30 | E3: =CONCATENATE(D3," ",C3," ",B3) -> 30 Nov 1992 | F3: =IF(M3<=30,"20-30",IF(M3<=40,"31-40",IF(M3<=50,"41-50","51+"))) -> 31-40 | G3: 570.62 | H3: tier - 2 | I3: tier - 1 | J3: R1013 | L3: =VLOOKUP(A3,'Customer Names'!$A$2:$B$2336,2,FALSE) -> Rosendahl | M3: =DATEDIF(E3,$K$2,"y") -> 32 | N3: =VLOOKUP(A3,'Medical Examinations'!$A$2:$B$2336,2,FALSE) -> 17.6 | O3: =VLOOKUP(A3,'Medical Examinations'!$A$1:$J$2336,3,FALSE) -> 4.39 | P3: =VLOOKUP(A3,'Medical Examinations'!$A$1:$J$2336,4,FALSE) -> No | Q3: =VLOOKUP(A3,'Medical Examinations'!$A$1:$J$2336,5,FALSE) -> No | R3: =VLOOKUP(A3,'Medical Examinations'!$A$1:$J$2336,7,FALSE) -> 1 | S3: =VLOOKUP(A3,'Medical Examinations'!$A$1:$J$2336,6,FALSE) -> No | T3: =VLOOKUP(A3,'Medical Examinations'!$A$1:$J$2336,8,FALSE) -> No | U3: =VLOOKUP(A3,'Medical Examinations'!$A$1:$J$2336,9,FALSE) -> Underweight | V3: =VLOOKUP(A3,'Medical Examinations'!$A$1:$J$2336,10,FALSE) -> Normal
A4: Id2333 | B4: 1993 | C4: Jun | D4: 30 | E4: =CONCATENATE(D4," ",C4," ",B4) -> 30 Jun 1993 | F4: =IF(M4<=30,"20-30",IF(M4<=40,"31-40",IF(M4<=50,"41-50","51+"))) -> 31-40 | G4: 600 | H4: tier - 2 | I4: tier - 1 | J4: R1013 | L4: =VLOOKUP(A4,'Customer Names'!$A$2:$B$2336,2,FALSE) -> Albano | M4: =DATEDIF(E4,$K$2,"y") -> 31 | N4: =VLOOKUP(A4,'Medical Examinations'!$A$2:$B$2336,2,FALSE) -> 16.47 | O4: =VLOOKUP(A4,'Medical Examinations'!$A$1:$J$2336,3,FALSE) -> 6.35 | P4: =VLOOKUP(A4,'Medical Examinations'!$A$1:$J$2336,4,FALSE) -> No | Q4: =VLOOKUP(A4,'Medical Examinations'!$A$1:$J$2336,5,FALSE) -> No | R4: =VLOOKUP(A4,'Medical Examinations'!$A$1:$J$2336,7,FALSE) -> 1 | S4: =VLOOKUP(A4,'Medical Examinations'!$A$1:$J$2336,6,FALSE) -> Yes | T4: =VLOOKUP(A4,'Medical Examinations'!$A$1:$J$2336,8,FALSE) -> No | U4: =VLOOKUP(A4,'Medical Examinations'!$A$1:$J$2336,9,FALSE) -> Underweight | V4: =VLOOKUP(A4,'Medical Examinations'!$A$1:$J$2336,10,FALSE) -> Prediabetes
A5: Id2332 | B5: 1992 | C5: Sep | D5: 13 | E5: =CONCATENATE(D5," ",C5," ",B5) -> 13 Sep 1992 | F5: =IF(M5<=30,"20-30",IF(M5<=40,"31-40",IF(M5<=50,"41-50","51+"))) -> 31-40 | G5: 604.54 | H5: tier - 3 | I5: tier - 3 | J5: R1013 | L5: =VLOOKUP(A5,'Customer Names'!$A$2:$B$2336,2,FALSE) -> Riveros Gonzalez | M5: =DATEDIF(E5,$K$2,"y") -> 32 | N5: =VLOOKUP(A5,'Medical Examinations'!$A$2:$B$2336,2,FALSE) -> 17.7 | O5: =VLOOKUP(A5,'Medical Examinations'!$A$1:$J$2336,3,FALSE) -> 6.28 | P5: =VLOOKUP(A5,'Medical Examinations'!$A$1:$J$2336,4,FALSE) -> No | Q5: =VLOOKUP(A5,'Medical Examinations'!$A$1:$J$2336,5,FALSE) -> No | R5: =VLOOKUP(A5,'Medical Examinations'!$A$1:$J$2336,7,FALSE) -> 1 | S5: =VLOOKUP(A5,'Medical Examinations'!$A$1:$J$2336,6,FALSE) -> No | T5: =VLOOKUP(A5,'Medical Examinations'!$A$1:$J$2336,8,FALSE) -> No | U5: =VLOOKUP(A5,'Medical Examinations'!$A$1:$J$2336,9,FALSE) -> Underweight | V5: =VLOOKUP(A5,'Medical Examinations'!$A$1:$J$2336,10,FALSE) -> Prediabetes
A6: Id2331 | B6: 1998 | C6: Jul | D6: 27 | E6: =CONCATENATE(D6," ",C6," ",B6) -> 27 Jul 1998 | F6: =IF(M6<=30,"20-30",IF(M6<=40,"31-40",IF(M6<=50,"41-50","51+"))) -> 20-30 | G6: 637.26 | H6: tier - 3 | I6: tier - 3 | J6: R1013 | L6: =VLOOKUP(A6,'Customer Names'!$A$2:$B$2336,2,FALSE) -> Brietzke | M6: =DATEDIF(E6,$K$2,"y") -> 26 | N6: =VLOOKUP(A6,'Medical Examinations'!$A$2:$B$2336,2,FALSE) -> 22.34 | O6: =VLOOKUP(A6,'Medical Examinations'!$A$1:$J$2336,3,FALSE) -> 5.57 | P6: =VLOOKUP(A6,'Medical Examinations'!$A$1:$J$2336,4,FALSE) -> No | Q6: =VLOOKUP(A6,'Medical Examinations'!$A$1:$J$2336,5,FALSE) -> No | R6: =VLOOKUP(A6,'Medical Examinations'!$A$1:$J$2336,7,FALSE) -> 1 | S6: =VLOOKUP(A6,'Medical Examinations'!$A$1:$J$2336,6,FALSE) -> No | T6: =VLOOKUP(A6,'Medical Examinations'!$A$1:$J$2336,8,FALSE) -> No | U6: =VLOOKUP(A6,'Medical Examinations'!$A$1:$J$2336,9,FALSE) -> Normal Weight | V6: =VLOOKUP(A6,'Medical Examinations'!$A$1:$J$2336,10,FALSE) -> Normal
A7: Id2330 | B7: 2001 | C7: Nov | D7: 20 | E7: =CONCATENATE(D7," ",C7," ",B7) -> 20 Nov 2001 | F7: =IF(M7<=30,"20-30",IF(M7<=40,"31-40",IF(M7<=50,"41-50","51+"))) -> 20-30 | G7: 646.14 | H7: tier - 3 | I7: tier - 3 | J7: R1012 | L7: =VLOOKUP(A7,'Customer Names'!$A$2:$B$2336,2,FALSE) -> Kohls | M7: =DATEDIF(E7,$K$2,"y") -> 23 | N7: =VLOOKUP(A7,'Medical Examinations'!$A$2:$B$2336,2,FALSE) -> 22.24 | O7: =VLOOKUP(A7,'Medical Examinations'!$A$1:$J$2336,3,FALSE) -> 4.29 | P7: =VLOOKUP(A7,'Medical Examinations'!$A$1:$J$2336,4,FALSE) -> Yes | Q7: =VLOOKUP(A7,'Medical Examinations'!$A$1:$J$2336,5,FALSE) -> No | R7: =VLOOKUP(A7,'Medical Examinations'!$A$1:$J$2336,7,FALSE) -> 0 | S7: =VLOOKUP(A7,'Medical Examinations'!$A$1:$J$2336,6,FALSE) -> No | T7: =VLOOKUP(A7,'Medical Examinations'!$A$1:$J$2336,8,FALSE) -> No | U7: =VLOOKUP(A7,'Medical Examinations'!$A$1:$J$2336,9,FALSE) -> Normal Weight | V7: =VLOOKUP(A7,'Medical Examinations'!$A$1:$J$2336,10,FALSE) -> Normal
A8: Id2329 | B8: 1993 | C8: Jun | D8: 1 | E8: =CONCATENATE(D8," ",C8," ",B8) -> 1 Jun 1993 | F8: =IF(M8<=30,"20-30",IF(M8<=40,"31-40",IF(M8<=50,"41-50","51+"))) -> 31-40 | G8: 650 | H8: tier - 3 | I8: tier - 3 | J8: R1013 | L8: =VLOOKUP(A8,'Customer Names'!$A$2:$B$2336,2,FALSE) -> Bohinski | M8: =DATEDIF(E8,$K$2,"y") -> 31 | N8: =VLOOKUP(A8,'Medical Examinations'!$A$2:$B$2336,2,FALSE) -> 17.07 | O8: =VLOOKUP(A8,'Medical Examinations'!$A$1:$J$2336,3,FALSE) -> 5.22 | P8: =VLOOKUP(A8,'Medical Examinations'!$A$1:$J$2336,4,FALSE) -> No | Q8: =VLOOKUP(A8,'Medical Examinations'!$A$1:$J$2336,5,FALSE) -> No | R8: =VLOOKUP(A8,'Medical Examinations'!$A$1:$J$2336,7,FALSE) -> 1 | S8: =VLOOKUP(A8,'Medical Examinations'!$A$1:$J$2336,6,FALSE) -> Yes | T8: =VLOOKUP(A8,'Medical Examinations'!$A$1:$J$2336,8,FALSE) -> No | U8: =VLOOKUP(A8,'Medical Examinations'!$A$1:$J$2336,9,FALSE) -> Underweight | V8: =VLOOKUP(A8,'Medical Examinations'!$A$1:$J$2336,10,FALSE) -> Normal
A9: Id2328 | B9: 1995 | C9: Jul | D9: 4 | E9: =CONCATENATE(D9," ",C9," ",B9) -> 4 Jul 1995 | F9: =IF(M9<=30,"20-30",IF(M9<=40,"31-40",IF(M9<=50,"41-50","51+"))) -> 20-30 | G9: 650 | H9: tier - 3 | I9: tier - 3 | J9: R1013 | L9: =VLOOKUP(A9,'Customer Names'!$A$2:$B$2336,2,FALSE) -> Avery | M9: =DATEDIF(E9,$K$2,"y") -> 29 | N9: =VLOOKUP(A9,'Medical Examinations'!$A$2:$B$2336,2,FALSE) -> 17.82 | O9: =VLOOKUP(A9,'Medical Examinations'!$A$1:$J$2336,3,FALSE) -> 5.26 | P9: =VLOOKUP(A9,'Medical Examinations'!$A$1:$J$2336,4,FALSE) -> Yes | Q9: =VLOOKUP(A9,'Medical Examinations'!$A$1:$J$2336,5,FALSE) -> No | R9: =VLOOKUP(A9,'Medical Examinations'!$A$1:$J$2336,7,FALSE) -> 1 | S9: =VLOOKUP(A9,'Medical Examinations'!$A$1:$J$2336,6,FALSE) -> No | T9: =VLOOKUP(A9,'Medical Examinations'!$A$1:$J$2336,8,FALSE) -> No | U9: =VLOOKUP(A9,'Medical Examinations'!$A$1:$J$2336,9,FALSE) -> Underweight | V9: =VLOOKUP(A9,'Medical Examinations'!$A$1:$J$2336,10,FALSE) -> Normal
A10: Id2327 | B10: 2002 | C10: Nov | D10: 29 | E10: =CONCATENATE(D10," ",C10," ",B10) -> 29 Nov 2002 | F10: =IF(M10<=30,"20-30",IF(M10<=40,"31-40",IF(M10<=50,"41-50","51+"))) -> 20-30 | G10: 668 | H10: tier - 3 | I10: tier - 2 | J10: R1012 | L10: =VLOOKUP(A10,'Customer Names'!$A$2:$B$2336,2,FALSE) -> Howell | M10: =DATEDIF(E10,$K$2,"y") -> 22 | N10: =VLOOKUP(A10,'Medical Examinations'!$A$2:$B$2336,2,FALSE) -> 21.77 | O10: =VLOOKUP(A10,'Medical Examinations'!$A$1:$J$2336,3,FALSE) -> 10.67 | P10: =VLOOKUP(A10,'Medical Examinations'!$A$1:$J$2336,4,FALSE) -> No | Q10: =VLOOKUP(A10,'Medical Examinations'!$A$1:$J$2336,5,FALSE) -> No | R10: =VLOOKUP(A10,'Medical Examinations'!$A$1:$J$2336,7,FALSE) -> 0 | S10: =VLOOKUP(A10,'Medical Examinations'!$A$1:$J$2336,6,FALSE) -> No | T10: =VLOOKUP(A10,'Medical Examinations'!$A$1:$J$2336,8,FALSE) -> No | U10: =VLOOKUP(A10,'Medical Examinations'!$A$1:$J$2336,9,FALSE) -> Normal Weight | V10: =VLOOKUP(A10,'Medical Examinations'!$A$1:$J$2336,10,FALSE) -> Diabetes
A11: Id2326 | B11: 1997 | C11: Nov | D11: 9 | E11: =CONCATENATE(D11," ",C11," ",B11) -> 9 Nov 1997 | F11: =IF(M11<=30,"20-30",IF(M11<=40,"31-40",IF(M11<=50,"41-50","51+"))) -> 20-30 | G11: 670 | H11: tier - 3 | I11: tier - 3 | J11: R1013 | L11: =VLOOKUP(A11,'Customer Names'!$A$2:$B$2336,2,FALSE) -> Castro | M11: =DATEDIF(E11,$K$2,"y") -> 27 | N11: =VLOOKUP(A11,'Medical Examinations'!$A$2:$B$2336,2,FALSE) -> 20.1 | O11: =VLOOKUP(A11,'Medical Examinations'!$A$1:$J$2336,3,FALSE) -> 5.6 | P11: =VLOOKUP(A11,'Medical Examinations'!$A$1:$J$2336,4,FALSE) -> Yes | Q11: =VLOOKUP(A11,'Medical Examinations'!$A$1:$J$2336,5,FALSE) -> No | R11: =VLOOKUP(A11,'Medical Examinations'!$A$1:$J$2336,7,FALSE) -> 1 | S11: =VLOOKUP(A11,'Medical Examinations'!$A$1:$J$2336,6,FALSE) -> Yes | T11: =VLOOKUP(A11,'Medical Examinations'!$A$1:$J$2336,8,FALSE) -> No | U11: =VLOOKUP(A11,'Medical Examinations'!$A$1:$J$2336,9,FALSE) -> Normal Weight | V11: =VLOOKUP(A11,'Medical Examinations'!$A$1:$J$2336,10,FALSE) -> Normal
A12: Id2325 | B12: 2001 | C12: Sep | D12: 12 | E12: =CONCATENATE(D12," ",C12," ",B12) -> 12 Sep 2001 | F12: =IF(M12<=30,"20-30",IF(M12<=40,"31-40",IF(M12<=50,"41-50","51+"))) -> 20-30 | G12: 687.54 | H12: tier - 3 | I12: tier - 2 | J12: R1013 | L12: =VLOOKUP(A12,'Customer Names'!$A$2:$B$2336,2,FALSE) -> Hines | M12: =DATEDIF(E12,$K$2,"y") -> 23 | N12: =VLOOKUP(A12,'Medical Examinations'!$A$2:$B$2336,2,FALSE) -> 24.76 | O12: =VLOOKUP(A12,'Medical Examinations'!$A$1:$J$2336,3,FALSE) -> 4.54 | P12: =VLOOKUP(A12,'Medical Examinations'!$A$1:$J$2336,4,FALSE) -> Yes | Q12: =VLOOKUP(A12,'Medical Examinations'!$A$1:$J$2336,5,FALSE) -> No | R12: =VLOOKUP(A12,'Medical Examinations'!$A$1:$J$2336,7,FALSE) -> 0 | S12: =VLOOKUP(A12,'Medical Examinations'!$A$1:$J$2336,6,FALSE) -> No | T12: =VLOOKUP(A12,'Medical Examinations'!$A$1:$J$2336,8,FALSE) -> No | U12: =VLOOKUP(A12,'Medical Examinations'!$A$1:$J$2336,9,FALSE) -> Normal Weight | V12: =VLOOKUP(A12,'Medical Examinations'!$A$1:$J$2336,10,FALSE) -> Normal
A13: Id2324 | B13: 1999 | C13: Dec | D13: 26 | E13: =CONCATENATE(D13," ",C13," ",B13) -> 26 Dec 1999 | F13: =IF(M13<=30,"20-30",IF(M13<=40,"31-40",IF(M13<=50,"41-50","51+"))) -> 20-30 | G13: 700 | H13: UNKNOWN | I13: tier - 3 | J13: R1013 | L13: =VLOOKUP(A13,'Customer Names'!$A$2:$B$2336,2,FALSE) -> Duffy | M13: =DATEDIF(E13,$K$2,"y") -> 25 | N13: =VLOOKUP(A13,'Medical Examinations'!$A$2:$B$2336,2,FALSE) -> 22.24 | O13: =VLOOKUP(A13,'Medical Examinations'!$A$1:$J$2336,3,FALSE) -> 5.04 | P13: =VLOOKUP(A13,'Medical Examinations'!$A$1:$J$2336,4,FALSE) -> No | Q13: =VLOOKUP(A13,'Medical Examinations'!$A$1:$J$2336,5,FALSE) -> No | R13: =VLOOKUP(A13,'Medical Examinations'!$A$1:$J$2336,7,FALSE) -> 0 | S13: =VLOOKUP(A13,'Medical Examinations'!$A$1:$J$2336,6,FALSE) -> No | T13: =VLOOKUP(A13,'Medical Examinations'!$A$1:$J$2336,8,FALSE) -> No | U13: =VLOOKUP(A13,'Medical Examinations'!$A$1:$J$2336,9,FALSE) -> Normal Weight | V13: =VLOOKUP(A13,'Medical Examinations'!$A$1:$J$2336,10,FALSE) -> Normal
A14: Id2323 | B14: 1999 | C14: Dec | D14: 14 | E14: =CONCATENATE(D14," ",C14," ",B14) -> 14 Dec 1999 | F14: =IF(M14<=30,"20-30",IF(M14<=40,"31-40",IF(M14<=50,"41-50","51+"))) -> 20-30 | G14: 722.99 | H14: tier - 3 | I14: tier - 1 | J14: R1013 | L14: =VLOOKUP(A14,'Customer Names'!$A$2:$B$2336,2,FALSE) -> Buss | M14: =DATEDIF(E14,$K$2,"y") -> 25 | N14: =VLOOKUP(A14,'Medical Examinations'!$A$2:$B$2336,2,FALSE) -> 23.35 | O14: =VLOOKUP(A14,'Medical Examinations'!$A$1:$J$2336,3,FALSE) -> 5.94 | P14: =VLOOKUP(A14,'Medical Examinations'!$A$1:$J$2336,4,FALSE) -> No | Q14: =VLOOKUP(A14,'Medical Examinations'!$A$1:$J$2336,5,FALSE) -> No | R14: =VLOOKUP(A14,'Medical Examinations'!$A$1:$J$2336,7,FALSE) -> 0 | S14: =VLOOKUP(A14,'Medical Examinations'!$A$1:$J$2336,6,FALSE) -> No | T14: =VLOOKUP(A14,'Medical Examinations'!$A$1:$J$2336,8,FALSE) -> No | U14: =VLOOKUP(A14,'Medical Examinations'!$A$1:$J$2336,9,FALSE) -> Normal Weight | V14: =VLOOKUP(A14,'Medical Examinations'!$A$1:$J$2336,10,FALSE) -> Prediabetes
... A1047: Id1290 | B1047: 1977 | C1047: Jul | D1047: 26 | E1047: =CONCATENATE(D1047," ",C1047," ",B1047) -> 26 Jul 1977 | F1047: =IF(M1047<=30,"20-30",IF(M1047<=40,"31-40",IF(M1047<=50,"41-50","51+"))) -> 41-50 | G1047: 8527.53 | H1047: tier - 2 | I1047: tier - 2 | J1047: R1013 | L1047: =VLOOKUP(A1047,'Customer Names'!$A$2:$B$2336,2,FALSE) -> Jean | M1047: =DATEDIF(E1047,$K$2,"y") -> 47 | N1047: =VLOOKUP(A1047,'Medical Examinations'!$A$2:$B$2336,2,FALSE) -> 36.3 | O1047: =VLOOKUP(A1047,'Medical Examinations'!$A$1:$J$2336,3,FALSE) -> 4.61 | P1047: =VLOOKUP(A1047,'Medical Examinations'!$A$1:$J$2336,4,FALSE) -> No | Q1047: =VLOOKUP(A1047,'Medical Examinations'!$A$1:$J$2336,5,FALSE) -> No | R1047: =VLOOKUP(A1047,'Medical Examinations'!$A$1:$J$2336,7,FALSE) -> 0 | S1047: =VLOOKUP(A1047,'Medical Examinations'!$A$1:$J$2336,6,FALSE) -> No | T1047: =VLOOKUP(A1047,'Medical Examinations'!$A$1:$J$2336,8,FALSE) -> No | U1047: =VLOOKUP(A1047,'Medical Examinations'!$A$1:$J$2336,9,FALSE) -> Obesity | V1047: =VLOOKUP(A1047,'Medical Examinations'!$A$1:$J$2336,10,FALSE) -> Normal
A1048: Id1289 | B1048: Sep | C1048: Jul | D1048: 24 | E1048: =CONCATENATE(D1048," ",C1048," ",B1048) -> 24 Jul Sep | F1048: =IF(M1048<=30,"20-30",IF(M1048<=40,"31-40",IF(M1048<=50,"41-50","51+"))) -> #VALUE! | G1048: 8534.67 | H1048: tier - 2 | I1048: tier - 3 | J1048: R1024 | L1048: =VLOOKUP(A1048,'Customer Names'!$A$2:$B$2336,2,FALSE) -> Levine | M1048: =DATEDIF(E1048,$K$2,"y") -> #VALUE! | N1048: =VLOOKUP(A1048,'Medical Examinations'!$A$2:$B$2336,2,FALSE) -> 24.32 | O1048: =VLOOKUP(A1048,'Medical Examinations'!$A$1:$J$2336,3,FALSE) -> 11.56 | P1048: =VLOOKUP(A1048,'Medical Examinations'!$A$1:$J$2336,4,FALSE) -> Yes | Q1048: =VLOOKUP(A1048,'Medical Examinations'!$A$1:$J$2336,5,FALSE) -> No | R1048: =VLOOKUP(A1048,'Medical Examinations'!$A$1:$J$2336,7,FALSE) -> 1 | S1048: =VLOOKUP(A1048,'Medical Examinations'!$A$1:$J$2336,6,FALSE) -> No | T1048: =VLOOKUP(A1048,'Medical Examinations'!$A$1:$J$2336,8,FALSE) -> No | U1048: =VLOOKUP(A1048,'Medical Examinations'!$A$1:$J$2336,9,FALSE) -> Normal Weight | V1048: =VLOOKUP(A1048,'Medical Examinations'!$A$1:$J$2336,10,FALSE) -> Diabetes
A1049: Id1288 | B1049: 1981 | C1049: Dec | D1049: 27 | E1049: =CONCATENATE(D1049," ",C1049," ",B1049) -> 27 Dec 1981 | F1049: =IF(M1049<=30,"20-30",IF(M1049<=40,"31-40",IF(M1049<=50,"41-50","51+"))) -> 41-50 | G1049: 8538.29 | H1049: tier - 2 | I1049: tier - 3 | J1049: R1024 | L1049: =VLOOKUP(A1049,'Customer Names'!$A$2:$B$2336,2,FALSE) -> Overpeck | M1049: =DATEDIF(E1049,$K$2,"y") -> 43 | N1049: =VLOOKUP(A1049,'Medical Examinations'!$A$2:$B$2336,2,FALSE) -> 33.155 | O1049: =VLOOKUP(A1049,'Medical Examinations'!$A$1:$J$2336,3,FALSE) -> 8.38 | P1049: =VLOOKUP(A1049,'Medical Examinations'!$A$1:$J$2336,4,FALSE) -> Yes | Q1049: =VLOOKUP(A1049,'Medical Examinations'!$A$1:$J$2336,5,FALSE) -> No | R1049: =VLOOKUP(A1049,'Medical Examinations'!$A$1:$J$2336,7,FALSE) -> 0 | S1049: =VLOOKUP(A1049,'Medical Examinations'!$A$1:$J$2336,6,FALSE) -> No | T1049: =VLOOKUP(A1049,'Medical Examinations'!$A$1:$J$2336,8,FALSE) -> No | U1049: =VLOOKUP(A1049,'Medical Examinations'!$A$1:$J$2336,9,FALSE) -> Obesity | V1049: =VLOOKUP(A1049,'Medical Examinations'!$A$1:$J$2336,10,FALSE) -> Diabetes
A1050: Id1287 | B1050: 1975 | C1050: Nov | D1050: 6 | E1050: =CONCATENATE(D1050," ",C1050," ",B1050) -> 6 Nov 1975 | F1050: =IF(M1050<=30,"20-30",IF(M1050<=40,"31-40",IF(M1050<=50,"41-50","51+"))) -> 41-50 | G1050: 8539.67 | H1050: tier - 2 | I1050: tier - 3 | J1050: R1011 | L1050: =VLOOKUP(A1050,'Customer Names'!$A$2:$B$2336,2,FALSE) -> Foster | M1050: =DATEDIF(E1050,$K$2,"y") -> 49 | N1050: =VLOOKUP(A1050,'Medical Examinations'!$A$2:$B$2336,2,FALSE) -> 23.6 | O1050: =VLOOKUP(A1050,'Medical Examinations'!$A$1:$J$2336,3,FALSE) -> 7.4 | P1050: =VLOOKUP(A1050,'Medical Examinations'!$A$1:$J$2336,4,FALSE) -> Yes | Q1050: =VLOOKUP(A1050,'Medical Examinations'!$A$1:$J$2336,5,FALSE) -> No | R1050: =VLOOKUP(A1050,'Medical Examinations'!$A$1:$J$2336,7,FALSE) -> 1 | S1050: =VLOOKUP(A1050,'Medical Examinations'!$A$1:$J$2336,6,FALSE) -> No | T1050: =VLOOKUP(A1050,'Medical Examinations'!$A$1:$J$2336,8,FALSE) -> No | U1050: =VLOOKUP(A1050,'Medical Examinations'!$A$1:$J$2336,9,FALSE) -> Normal Weight | V1050: =VLOOKUP(A1050,'Medical Examinations'!$A$1:$J$2336,10,FALSE) -> Diabetes
A1051: Id1286 | B1051: Sep | C1051: Dec | D1051: 12 | E1051: =CONCATENATE(D1051," ",C1051," ",B1051) -> 12 Dec Sep | F1051: =IF(M1051<=30,"20-30",IF(M1051<=40,"31-40",IF(M1051<=50,"41-50","51+"))) -> #VALUE! | G1051: 8547.69 | H1051: tier - 2 | I1051: tier - 1 | J1051: R1013 | L1051: =VLOOKUP(A1051,'Customer Names'!$A$2:$B$2336,2,FALSE) -> Ainsley | M1051: =DATEDIF(E1051,$K$2,"y") -> #VALUE! | N1051: =VLOOKUP(A1051,'Medical Examinations'!$A$2:$B$2336,2,FALSE) -> 29.37 | O1051: =VLOOKUP(A1051,'Medical Examinations'!$A$1:$J$2336,3,FALSE) -> 8.01 | P1051: =VLOOKUP(A1051,'Medical Examinations'!$A$1:$J$2336,4,FALSE) -> Yes | Q1051: =VLOOKUP(A1051,'Medical Examinations'!$A$1:$J$2336,5,FALSE) -> No | R1051: =VLOOKUP(A1051,'Medical Examinations'!$A$1:$J$2336,7,FALSE) -> 1 | S1051: =VLOOKUP(A1051,'Medical Examinations'!$A$1:$J$2336,6,FALSE) -> No | T1051: =VLOOKUP(A1051,'Medical Examinations'!$A$1:$J$2336,8,FALSE) -> No | U1051: =VLOOKUP(A1051,'Medical Examinations'!$A$1:$J$2336,9,FALSE) -> Overweight | V1051: =VLOOKUP(A1051,'Medical Examinations'!$A$1:$J$2336,10,FALSE) -> Diabetes
A1052: Id1285 | B1052: 1975 | C1052: Aug | D1052: 6 | E1052: =CONCATENATE(D1052," ",C1052," ",B1052) -> 6 Aug 1975 | F1052: =IF(M1052<=30,"20-30",IF(M1052<=40,"31-40",IF(M1052<=50,"41-50","51+"))) -> 41-50 | G1052: 8551.35 | H1052: tier - 2 | I1052: tier - 2 | J1052: R1011 | L1052: =VLOOKUP(A1052,'Customer Names'!$A$2:$B$2336,2,FALSE) -> Bokun | M1052: =DATEDIF(E1052,$K$2,"y") -> 49 | N1052: =VLOOKUP(A1052,'Medical Examinations'!$A$2:$B$2336,2,FALSE) -> 32 | O1052: =VLOOKUP(A1052,'Medical Examinations'!$A$1:$J$2336,3,FALSE) -> 7.85 | P1052: =VLOOKUP(A1052,'Medical Examinations'!$A$1:$J$2336,4,FALSE) -> Yes | Q1052: =VLOOKUP(A1052,'Medical Examinations'!$A$1:$J$2336,5,FALSE) -> No | R1052: =VLOOKUP(A1052,'Medical Examinations'!$A$1:$J$2336,7,FALSE) -> 1 | S1052: =VLOOKUP(A1052,'Medical Examinations'!$A$1:$J$2336,6,FALSE) -> No | T1052: =VLOOKUP(A1052,'Medical Examinations'!$A$1:$J$2336,8,FALSE) -> No | U1052: =VLOOKUP(A1052,'Medical Examinations'!$A$1:$J$2336,9,FALSE) -> Obesity | V1052: =VLOOKUP(A1052,'Medical Examinations'!$A$1:$J$2336,10,FALSE) -> Diabetes
A1053: Id1284 | B1053: 1975 | C1053: Aug | D1053: 21 | E1053: =CONCATENATE(D1053," ",C1053," ",B1053) -> 21 Aug 1975 | F1053: =IF(M1053<=30,"20-30",IF(M1053<=40,"31-40",IF(M1053<=50,"41-50","51+"))) -> 41-50 | G1053: 8556.91 | H1053: tier - 2 | I1053: tier - 1 | J1053: R1011 | L1053: =VLOOKUP(A1053,'Customer Names'!$A$2:$B$2336,2,FALSE) -> Wegner | M1053: =DATEDIF(E1053,$K$2,"y") -> 49 | N1053: =VLOOKUP(A1053,'Medical Examinations'!$A$2:$B$2336,2,FALSE) -> 36 | O1053: =VLOOKUP(A1053,'Medical Examinations'!$A$1:$J$2336,3,FALSE) -> 11.94 | P1053: =VLOOKUP(A1053,'Medical Examinations'!$A$1:$J$2336,4,FALSE) -> Yes | Q1053: =VLOOKUP(A1053,'Medical Examinations'!$A$1:$J$2336,5,FALSE) -> No | R1053: =VLOOKUP(A1053,'Medical Examinations'!$A$1:$J$2336,7,FALSE) -> 1 | S1053: =VLOOKUP(A1053,'Medical Examinations'!$A$1:$J$2336,6,FALSE) -> No | T1053: =VLOOKUP(A1053,'Medical Examinations'!$A$1:$J$2336,8,FALSE) -> No | U1053: =VLOOKUP(A1053,'Medical Examinations'!$A$1:$J$2336,9,FALSE) -> Obesity | V1053: =VLOOKUP(A1053,'Medical Examinations'!$A$1:$J$2336,10,FALSE) -> Diabetes
A1054: Id1283 | B1054: 1988 | C1054: Sep | D1054: 21 | E1054: =CONCATENATE(D1054," ",C1054," ",B1054) -> 21 Sep 1988 | F1054: =IF(M1054<=30,"20-30",IF(M1054<=40,"31-40",IF(M1054<=50,"41-50","51+"))) -> 31-40 | G1054: 8567.25 | H1054: tier - 2 | I1054: tier - 1 | J1054: R1012 | L1054: =VLOOKUP(A1054,'Customer Names'!$A$2:$B$2336,2,FALSE) -> Reed | M1054: =DATEDIF(E1054,$K$2,"y") -> 36 | N1054: =VLOOKUP(A1054,'Medical Examinations'!$A$2:$B$2336,2,FALSE) -> 31.93 | O1054: =VLOOKUP(A1054,'Medical Examinations'!$A$1:$J$2336,3,FALSE) -> 4.82 | P1054: =VLOOKUP(A1054,'Medical Examinations'!$A$1:$J$2336,4,FALSE) -> Yes | Q1054: =VLOOKUP(A1054,'Medical Examinations'!$A$1:$J$2336,5,FALSE) -> No | R1054: =VLOOKUP(A1054,'Medical Examinations'!$A$1:$J$2336,7,FALSE) -> 1 | S1054: =VLOOKUP(A1054,'Medical Examinations'!$A$1:$J$2336,6,FALSE) -> No | T1054: =VLOOKUP(A1054,'Medical Examinations'!$A$1:$J$2336,8,FALSE) -> No | U1054: =VLOOKUP(A1054,'Medical Examinations'!$A$1:$J$2336,9,FALSE) -> Obesity | V1054: =VLOOKUP(A1054,'Medical Examinations'!$A$1:$J$2336,10,FALSE) -> Normal
A1055: Id1282 | B1055: 1975 | C1055: Sep | D1055: 26 | E1055: =CONCATENATE(D1055," ",C1055," ",B1055) -> 26 Sep 1975 | F1055: =IF(M1055<=30,"20-30",IF(M1055<=40,"31-40",IF(M1055<=50,"41-50","51+"))) -> 41-50 | G1055: 8569.86 | H1055: tier - 2 | I1055: tier - 3 | J1055: R1013 | L1055: =VLOOKUP(A1055,'Customer Names'!$A$2:$B$2336,2,FALSE) -> Amato | M1055: =DATEDIF(E1055,$K$2,"y") -> 49 | N1055: =VLOOKUP(A1055,'Medical Examinations'!$A$2:$B$2336,2,FALSE) -> 45.32 | O1055: =VLOOKUP(A1055,'Medical Examinations'!$A$1:$J$2336,3,FALSE) -> 6.53 | P1055: =VLOOKUP(A1055,'Medical Examinations'!$A$1:$J$2336,4,FALSE) -> Yes | Q1055: =VLOOKUP(A1055,'Medical Examinations'!$A$1:$J$2336,5,FALSE) -> No | R1055: =VLOOKUP(A1055,'Medical Examinations'!$A$1:$J$2336,7,FALSE) -> 1 | S1055: =VLOOKUP(A1055,'Medical Examinations'!$A$1:$J$2336,6,FALSE) -> No | T1055: =VLOOKUP(A1055,'Medical Examinations'!$A$1:$J$2336,8,FALSE) -> No | U1055: =VLOOKUP(A1055,'Medical Examinations'!$A$1:$J$2336,9,FALSE) -> Obesity | V1055: =VLOOKUP(A1055,'Medical Examinations'!$A$1:$J$2336,10,FALSE) -> Diabetes
A1056: Id1281 | B1056: 1982 | C1056: Dec | D1056: 6 | E1056: =CONCATENATE(D1056," ",C1056," ",B1056) -> 6 Dec 1982 | F1056: =IF(M1056<=30,"20-30",IF(M1056<=40,"31-40",IF(M1056<=50,"41-50","51+"))) -> 41-50 | G1056: 8572.04 | H1056: tier - 2 | I1056: tier - 2 | J1056: R1021 | L1056: =VLOOKUP(A1056,'Customer Names'!$A$2:$B$2336,2,FALSE) -> O'Hora | M1056: =DATEDIF(E1056,$K$2,"y") -> 42 | N1056: =VLOOKUP(A1056,'Medical Examinations'!$A$2:$B$2336,2,FALSE) -> 26.36 | O1056: =VLOOKUP(A1056,'Medical Examinations'!$A$1:$J$2336,3,FALSE) -> 5.52 | P1056: =VLOOKUP(A1056,'Medical Examinations'!$A$1:$J$2336,4,FALSE) -> No | Q1056: =VLOOKUP(A1056,'Medical Examinations'!$A$1:$J$2336,5,FALSE) -> No | R1056: =VLOOKUP(A1056,'Medical Examinations'!$A$1:$J$2336,7,FALSE) -> 0 | S1056: =VLOOKUP(A1056,'Medical Examinations'!$A$1:$J$2336,6,FALSE) -> No | T1056: =VLOOKUP(A1056,'Medical Examinations'!$A$1:$J$2336,8,FALSE) -> No | U1056: =VLOOKUP(A1056,'Medical Examinations'!$A$1:$J$2336,9,FALSE) -> Overweight | V1056: =VLOOKUP(A1056,'Medical Examinations'!$A$1:$J$2336,10,FALSE) -> Normal
A1057: Id1280 | B1057: 1987 | C1057: Nov | D1057: 11 | E1057: =CONCATENATE(D1057," ",C1057," ",B1057) -> 11 Nov 1987 | F1057: =IF(M1057<=30,"20-30",IF(M1057<=40,"31-40",IF(M1057<=50,"41-50","51+"))) -> 31-40 | G1057: 8573.3 | H1057: tier - 2 | I1057: tier - 2 | J1057: R1021 | L1057: =VLOOKUP(A1057,'Customer Names'!$A$2:$B$2336,2,FALSE) -> Jacobsen | M1057: =DATEDIF(E1057,$K$2,"y") -> 37 | N1057: =VLOOKUP(A1057,'Medical Examinations'!$A$2:$B$2336,2,FALSE) -> 30.15 | O1057: =VLOOKUP(A1057,'Medical Examinations'!$A$1:$J$2336,3,FALSE) -> 4.25 | P1057: =VLOOKUP(A1057,'Medical Examinations'!$A$1:$J$2336,4,FALSE) -> No | Q1057: =VLOOKUP(A1057,'Medical Examinations'!$A$1:$J$2336,5,FALSE) -> No | R1057: =VLOOKUP(A1057,'Medical Examinations'!$A$1:$J$2336,7,FALSE) -> 1 | S1057: =VLOOKUP(A1057,'Medical Examinations'!$A$1:$J$2336,6,FALSE) -> No | T1057: =VLOOKUP(A1057,'Medical Examinations'!$A$1:$J$2336,8,FALSE) -> No | U1057: =VLOOKUP(A1057,'Medical Examinations'!$A$1:$J$2336,9,FALSE) -> Obesity | V1057: =VLOOKUP(A1057,'Medical Examinations'!$A$1:$J$2336,10,FALSE) -> Normal
A1058: Id1279 | B1058: 1983 | C1058: Dec | D1058: 30 | E1058: =CONCATENATE(D1058," ",C1058," ",B1058) -> 30 Dec 1983 | F1058: =IF(M1058<=30,"20-30",IF(M1058<=40,"31-40",IF(M1058<=50,"41-50","51+"))) -> 41-50 | G1058: 8582.3 | H1058: tier - 2 | I1058: tier - 1 | J1058: R1013 | L1058: =VLOOKUP(A1058,'Customer Names'!$A$2:$B$2336,2,FALSE) -> Roach | M1058: =DATEDIF(E1058,$K$2,"y") -> 41 | N1058: =VLOOKUP(A1058,'Medical Examinations'!$A$2:$B$2336,2,FALSE) -> 23.87 | O1058: =VLOOKUP(A1058,'Medical Examinations'!$A$1:$J$2336,3,FALSE) -> 4.77 | P1058: =VLOOKUP(A1058,'Medical Examinations'!$A$1:$J$2336,4,FALSE) -> Yes | Q1058: =VLOOKUP(A1058,'Medical Examinations'!$A$1:$J$2336,5,FALSE) -> No | R1058: =VLOOKUP(A1058,'Medical Examinations'!$A$1:$J$2336,7,FALSE) -> 1 | S1058: =VLOOKUP(A1058,'Medical Examinations'!$A$1:$J$2336,6,FALSE) -> Yes | T1058: =VLOOKUP(A1058,'Medical Examinations'!$A$1:$J$2336,8,FALSE) -> No | U1058: =VLOOKUP(A1058,'Medical Examinations'!$A$1:$J$2336,9,FALSE) -> Normal Weight | V1058: =VLOOKUP(A1058,'Medical Examinations'!$A$1:$J$2336,10,FALSE) -> Normal
A1059: Id1278 | B1059: 1983 | C1059: Jul | D1059: 25 | E1059: =CONCATENATE(D1059," ",C1059," ",B1059) -> 25 Jul 1983 | F1059: =IF(M1059<=30,"20-30",IF(M1059<=40,"31-40",IF(M1059<=50,"41-50","51+"))) -> 41-50 | G1059: 8596.83 | H1059: tier - 2 | I1059: tier - 3 | J1059: R1013 | L1059: =VLOOKUP(A1059,'Customer Names'!$A$2:$B$2336,2,FALSE) -> Willsey | M1059: =DATEDIF(E1059,$K$2,"y") -> 41 | N1059: =VLOOKUP(A1059,'Medical Examinations'!$A$2:$B$2336,2,FALSE) -> 34.32 | O1059: =VLOOKUP(A1059,'Medical Examinations'!$A$1:$J$2336,3,FALSE) -> 5.7 | P1059: =VLOOKUP(A1059,'Medical Examinations'!$A$1:$J$2336,4,FALSE) -> Yes | Q1059: =VLOOKUP(A1059,'Medical Examinations'!$A$1:$J$2336,5,FALSE) -> No | R1059: =VLOOKUP(A1059,'Medical Examinations'!$A$1:$J$2336,7,FALSE) -> 1 | S1059: =VLOOKUP(A1059,'Medical Examinations'!$A$1:$J$2336,6,FALSE) -> Yes | T1059: =VLOOKUP(A1059,'Medical Examinations'!$A$1:$J$2336,8,FALSE) -> No | U1059: =VLOOKUP(A1059,'Medical Examinations'!$A$1:$J$2336,9,FALSE) -> Obesity | V1059: =VLOOKUP(A1059,'Medical Examinations'!$A$1:$J$2336,10,FALSE) -> Prediabetes
A1060: Id1277 | B1060: 1973 | C1060: Jul | D1060: 11 | E1060: =CONCATENATE(D1060," ",C1060," ",B1060) -> 11 Jul 1973 | F1060: =IF(M1060<=30,"20-30",IF(M1060<=40,"31-40",IF(M1060<=50,"41-50","51+"))) -> 51+ | G1060: 8601.33 | H1060: tier - 2 | I1060: tier - 1 | J1060: R1013 | L1060: =VLOOKUP(A1060,'Customer Names'!$A$2:$B$2336,2,FALSE) -> Pretot | M1060: =DATEDIF(E1060,$K$2,"y") -> 51 | N1060: =VLOOKUP(A1060,'Medical Examinations'!$A$2:$B$2336,2,FALSE) -> 27.17 | O1060: =VLOOKUP(A1060,'Medical Examinations'!$A$1:$J$2336,3,FALSE) -> 10.81 | P1060: =VLOOKUP(A1060,'Medical Examinations'!$A$1:$J$2336,4,FALSE) -> No | Q1060: =VLOOKUP(A1060,'Medical Examinations'!$A$1:$J$2336,5,FALSE) -> No | R1060: =VLOOKUP(A1060,'Medical Examinations'!$A$1:$J$2336,7,FALSE) -> 2 | S1060: =VLOOKUP(A1060,'Medical Examinations'!$A$1:$J$2336,6,FALSE) -> No | T1060: =VLOOKUP(A1060,'Medical Examinations'!$A$1:$J$2336,8,FALSE) -> No | U1060: =VLOOKUP(A1060,'Medical Examinations'!$A$1:$J$2336,9,FALSE) -> Overweight | V1060: =VLOOKUP(A1060,'Medical Examinations'!$A$1:$J$2336,10,FALSE) -> Diabetes
A1061: Id1276 | B1061: 1977 | C1061: Sep | D1061: 24 | E1061: =CONCATENATE(D1061," ",C1061," ",B1061) -> 24 Sep 1977 | F1061: =IF(M1061<=30,"20-30",IF(M1061<=40,"31-40",IF(M1061<=50,"41-50","51+"))) -> 41-50 | G1061: 8603.82 | H1061: tier - 2 | I1061: tier - 1 | J1061: R1019 | L1061: =VLOOKUP(A1061,'Customer Names'!$A$2:$B$2336,2,FALSE) -> Deeg | M1061: =DATEDIF(E1061,$K$2,"y") -> 47 | N1061: =VLOOKUP(A1061,'Medical Examinations'!$A$2:$B$2336,2,FALSE) -> 23.56 | O1061: =VLOOKUP(A1061,'Medical Examinations'!$A$1:$J$2336,3,FALSE) -> 5.97 | P1061: =VLOOKUP(A1061,'Medical Examinations'!$A$1:$J$2336,4,FALSE) -> No | Q1061: =VLOOKUP(A1061,'Medical Examinations'!$A$1:$J$2336,5,FALSE) -> No | R1061: =VLOOKUP(A1061,'Medical Examinations'!$A$1:$J$2336,7,FALSE) -> 0 | S1061: =VLOOKUP(A1061,'Medical Examinations'!$A$1:$J$2336,6,FALSE) -> No | T1061: =VLOOKUP(A1061,'Medical Examinations'!$A$1:$J$2336,8,FALSE) -> No | U1061: =VLOOKUP(A1061,'Medical Examinations'!$A$1:$J$2336,9,FALSE) -> Normal Weight | V1061: =VLOOKUP(A1061,'Medical Examinations'!$A$1:$J$2336,10,FALSE) -> Prediabetes
A1062: Id1275 | B1062: 1977 | C1062: Nov | D1062: 12 | E1062: =CONCATENATE(D1062," ",C1062," ",B1062) -> 12 Nov 1977 | F1062: =IF(M1062<=30,"20-30",IF(M1062<=40,"31-40",IF(M1062<=50,"41-50","51+"))) -> 41-50 | G1062: 8604.48 | H1062: tier - 3 | I1062: tier - 2 | J1062: R1016 | L1062: =VLOOKUP(A1062,'Customer Names'!$A$2:$B$2336,2,FALSE) -> Ritter | M1062: =DATEDIF(E1062,$K$2,"y") -> 47 | N1062: =VLOOKUP(A1062,'Medical Examinations'!$A$2:$B$2336,2,FALSE) -> 24.035 | O1062: =VLOOKUP(A1062,'Medical Examinations'!$A$1:$J$2336,3,FALSE) -> 6.11 | P1062: =VLOOKUP(A1062,'Medical Examinations'!$A$1:$J$2336,4,FALSE) -> No | Q1062: =VLOOKUP(A1062,'Medical Examinations'!$A$1:$J$2336,5,FALSE) -> No | R1062: =VLOOKUP(A1062,'Medical Examinations'!$A$1:$J$2336,7,FALSE) -> 0 | S1062: =VLOOKUP(A1062,'Medical Examinations'!$A$1:$J$2336,6,FALSE) -> No | T1062: =VLOOKUP(A1062,'Medical Examinations'!$A$1:$J$2336,8,FALSE) -> No | U1062: =VLOOKUP(A1062,'Medical Examinations'!$A$1:$J$2336,9,FALSE) -> Normal Weight | V1062: =VLOOKUP(A1062,'Medical Examinations'!$A$1:$J$2336,10,FALSE) -> Prediabetes
A1063: Id1274 | B1063: 1977 | C1063: Oct | D1063: 15 | E1063: =CONCATENATE(D1063," ",C1063," ",B1063) -> 15 Oct 1977 | F1063: =IF(M1063<=30,"20-30",IF(M1063<=40,"31-40",IF(M1063<=50,"41-50","51+"))) -> 41-50 | G1063: 8605.36 | H1063: tier - 2 | I1063: tier - 2 | J1063: R1013 | L1063: =VLOOKUP(A1063,'Customer Names'!$A$2:$B$2336,2,FALSE) -> Scheibel | M1063: =DATEDIF(E1063,$K$2,"y") -> 47 | N1063: =VLOOKUP(A1063,'Medical Examinations'!$A$2:$B$2336,2,FALSE) -> 20.35 | O1063: =VLOOKUP(A1063,'Medical Examinations'!$A$1:$J$2336,3,FALSE) -> 4.16 | P1063: =VLOOKUP(A1063,'Medical Examinations'!$A$1:$J$2336,4,FALSE) -> No | Q1063: =VLOOKUP(A1063,'Medical Examinations'!$A$1:$J$2336,5,FALSE) -> No | R1063: =VLOOKUP(A1063,'Medical Examinations'!$A$1:$J$2336,7,FALSE) -> 0 | S1063: =VLOOKUP(A1063,'Medical Examinations'!$A$1:$J$2336,6,FALSE) -> No | T1063: =VLOOKUP(A1063,'Medical Examinations'!$A$1:$J$2336,8,FALSE) -> No | U1063: =VLOOKUP(A1063,'Medical Examinations'!$A$1:$J$2336,9,FALSE) -> Normal Weight | V1063: =VLOOKUP(A1063,'Medical Examinations'!$A$1:$J$2336,10,FALSE) -> Normal
... A1701: Id636 | B1701: 1976 | C1701: Jul | D1701: 20 | E1701: =CONCATENATE(D1701," ",C1701," ",B1701) -> 20 Jul 1976 | F1701: =IF(M1701<=30,"20-30",IF(M1701<=40,"31-40",IF(M1701<=50,"41-50","51+"))) -> 41-50 | G1701: 15450.48 | H1701: tier - 2 | I1701: tier - 1 | J1701: R1026 | L1701: =VLOOKUP(A1701,'Customer Names'!$A$2:$B$2336,2,FALSE) -> Stoney | M1701: =DATEDIF(E1701,$K$2,"y") -> 48 | N1701: =VLOOKUP(A1701,'Medical Examinations'!$A$2:$B$2336,2,FALSE) -> 43.11 | O1701: =VLOOKUP(A1701,'Medical Examinations'!$A$1:$J$2336,3,FALSE) -> 4.67 | P1701: =VLOOKUP(A1701,'Medical Examinations'!$A$1:$J$2336,4,FALSE) -> Yes | Q1701: =VLOOKUP(A1701,'Medical Examinations'!$A$1:$J$2336,5,FALSE) -> No | R1701: =VLOOKUP(A1701,'Medical Examinations'!$A$1:$J$2336,7,FALSE) -> 0 | S1701: =VLOOKUP(A1701,'Medical Examinations'!$A$1:$J$2336,6,FALSE) -> No | T1701: =VLOOKUP(A1701,'Medical Examinations'!$A$1:$J$2336,8,FALSE) -> No | U1701: =VLOOKUP(A1701,'Medical Examinations'!$A$1:$J$2336,9,FALSE) -> Obesity | V1701: =VLOOKUP(A1701,'Medical Examinations'!$A$1:$J$2336,10,FALSE) -> Normal
A1702: Id635 | B1702: 2004 | C1702: Jul | D1702: 17 | E1702: =CONCATENATE(D1702," ",C1702," ",B1702) -> 17 Jul 2004 | F1702: =IF(M1702<=30,"20-30",IF(M1702<=40,"31-40",IF(M1702<=50,"41-50","51+"))) -> 20-30 | G1702: 15518.18 | H1702: tier - 2 | I1702: tier - 3 | J1702: R1015 | L1702: =VLOOKUP(A1702,'Customer Names'!$A$2:$B$2336,2,FALSE) -> Bruns | M1702: =DATEDIF(E1702,$K$2,"y") -> 20 | N1702: =VLOOKUP(A1702,'Medical Examinations'!$A$2:$B$2336,2,FALSE) -> 25.175 | O1702: =VLOOKUP(A1702,'Medical Examinations'!$A$1:$J$2336,3,FALSE) -> 4.96 | P1702: =VLOOKUP(A1702,'Medical Examinations'!$A$1:$J$2336,4,FALSE) -> No | Q1702: =VLOOKUP(A1702,'Medical Examinations'!$A$1:$J$2336,5,FALSE) -> Yes | R1702: =VLOOKUP(A1702,'Medical Examinations'!$A$1:$J$2336,7,FALSE) -> 1 | S1702: =VLOOKUP(A1702,'Medical Examinations'!$A$1:$J$2336,6,FALSE) -> No | T1702: =VLOOKUP(A1703,'Medical Examinations'!$A$1:$J$2336,8,FALSE) -> No | U1702: =VLOOKUP(A1702,'Medical Examinations'!$A$1:$J$2336,9,FALSE) -> Overweight | V1702: =VLOOKUP(A1702,'Medical Examinations'!$A$1:$J$2336,10,FALSE) -> Normal
A1703: Id634 | B1703: 1974 | C1703: Jun | D1703: 28 | E1703: =CONCATENATE(D1703," ",C1703," ",B1703) -> 28 Jun 1974 | F1703: =IF(M1703<=30,"20-30",IF(M1703<=40,"31-40",IF(M1703<=50,"41-50","51+"))) -> 41-50 | G1703: 15532.16 | H1703: tier - 2 | I1703: tier - 2 | J1703: R1026 | L1703: =VLOOKUP(A1703,'Customer Names'!$A$2:$B$2336,2,FALSE) -> Lovlien | M1703: =DATEDIF(E1703,$K$2,"y") -> 50 | N1703: =VLOOKUP(A1703,'Medical Examinations'!$A$2:$B$2336,2,FALSE) -> 44.64 | O1703: =VLOOKUP(A1703,'Medical Examinations'!$A$1:$J$2336,3,FALSE) -> 7.18 | P1703: =VLOOKUP(A1703,'Medical Examinations'!$A$1:$J$2336,4,FALSE) -> No | Q1703: =VLOOKUP(A1703,'Medical Examinations'!$A$1:$J$2336,5,FALSE) -> No | R1703: =VLOOKUP(A1703,'Medical Examinations'!$A$1:$J$2336,7,FALSE) -> 0 | S1703: =VLOOKUP(A1703,'Medical Examinations'!$A$1:$J$2336,6,FALSE) -> No | T1703: =VLOOKUP(A1704,'Medical Examinations'!$A$1:$J$2336,8,FALSE) -> No | U1703: =VLOOKUP(A1703,'Medical Examinations'!$A$1:$J$2336,9,FALSE) -> Obesity | V1703: =VLOOKUP(A1703,'Medical Examinations'!$A$1:$J$2336,10,FALSE) -> Diabetes
A1704: Id633 | B1704: 1959 | C1704: Oct | D1704: 2 | E1704: =CONCATENATE(D1704," ",C1704," ",B1704) -> 2 Oct 1959 | F1704: =IF(M1704<=30,"20-30",IF(M1704<=40,"31-40",IF(M1704<=50,"41-50","51+"))) -> 51+ | G1704: 15555.19 | H1704: tier - 2 | I1704: tier - 3 | J1704: R1012 | L1704: =VLOOKUP(A1704,'Customer Names'!$A$2:$B$2336,2,FALSE) -> Mutai | M1704: =DATEDIF(E1704,$K$2,"y") -> 65 | N1704: =VLOOKUP(A1704,'Medical Examinations'!$A$2:$B$2336,2,FALSE) -> 41.325 | O1704: =VLOOKUP(A1704,'Medical Examinations'!$A$1:$J$2336,3,FALSE) -> 5.11 | P1704: =VLOOKUP(A1704,'Medical Examinations'!$A$1:$J$2336,4,FALSE) -> Yes | Q1704: =VLOOKUP(A1704,'Medical Examinations'!$A$1:$J$2336,5,FALSE) -> No | R1704: =VLOOKUP(A1704,'Medical Examinations'!$A$1:$J$2336,7,FALSE) -> 2 | S1704: =VLOOKUP(A1704,'Medical Examinations'!$A$1:$J$2336,6,FALSE) -> No | T1704: =VLOOKUP(A1705,'Medical Examinations'!$A$1:$J$2336,8,FALSE) -> No | U1704: =VLOOKUP(A1704,'Medical Examinations'!$A$1:$J$2336,9,FALSE) -> Obesity | V1704: =VLOOKUP(A1704,'Medical Examinations'!$A$1:$J$2336,10,FALSE) -> Normal
A1705: Id632 | B1705: 1974 | C1705: Jul | D1705: 30 | E1705: =CONCATENATE(D1705," ",C1705," ",B1705) -> 30 Jul 1974 | F1705: =IF(M1705<=30,"20-30",IF(M1705<=40,"31-40",IF(M1705<=50,"41-50","51+"))) -> 41-50 | G1705: 15556.67 | H1705: tier - 2 | I1705: tier - 2 | J1705: R1012 | L1705: =VLOOKUP(A1705,'Customer Names'!$A$2:$B$2336,2,FALSE) -> Drotz | M1705: =DATEDIF(E1705,$K$2,"y") -> 50 | N1705: =VLOOKUP(A1705,'Medical Examinations'!$A$2:$B$2336,2,FALSE) -> 46.14 | O1705: =VLOOKUP(A1705,'Medical Examinations'!$A$1:$J$2336,3,FALSE) -> 10.78 | P1705: =VLOOKUP(A1705,'Medical Examinations'!$A$1:$J$2336,4,FALSE) -> No | Q1705: =VLOOKUP(A1705,'Medical Examinations'!$A$1:$J$2336,5,FALSE) -> No | R1705: =VLOOKUP(A1705,'Medical Examinations'!$A$1:$J$2336,7,FALSE) -> 0 | S1705: =VLOOKUP(A1705,'Medical Examinations'!$A$1:$J$2336,6,FALSE) -> No | T1705: =VLOOKUP(A1706,'Medical Examinations'!$A$1:$J$2336,8,FALSE) -> No | U1705: =VLOOKUP(A1705,'Medical Examinations'!$A$1:$J$2336,9,FALSE) -> Obesity | V1705: =VLOOKUP(A1705,'Medical Examinations'!$A$1:$J$2336,10,FALSE) -> Diabetes
A1706: Id631 | B1706: 1965 | C1706: Oct | D1706: 28 | E1706: =CONCATENATE(D1706," ",C1706," ",B1706) -> 28 Oct 1965 | F1706: =IF(M1706<=30,"20-30",IF(M1706<=40,"31-40",IF(M1706<=50,"41-50","51+"))) -> 51+ | G1706: 15608.58 | H1706: tier - 2 | I1706: tier - 2 | J1706: R1026 | L1706: =VLOOKUP(A1706,'Customer Names'!$A$2:$B$2336,2,FALSE) -> Stewart | M1706: =DATEDIF(E1706,$K$2,"y") -> 59 | N1706: =VLOOKUP(A1706,'Medical Examinations'!$A$2:$B$2336,2,FALSE) -> 38.05 | O1706: =VLOOKUP(A1706,'Medical Examinations'!$A$1:$J$2336,3,FALSE) -> 9.62 | P1706: =VLOOKUP(A1706,'Medical Examinations'!$A$1:$J$2336,4,FALSE) -> No | Q1706: =VLOOKUP(A1706,'Medical Examinations'!$A$1:$J$2336,5,FALSE) -> No | R1706: =VLOOKUP(A1706,'Medical Examinations'!$A$1:$J$2336,7,FALSE) -> 0 | S1706: =VLOOKUP(A1706,'Medical Examinations'!$A$1:$J$2336,6,FALSE) -> No | T1706: =VLOOKUP(A1707,'Medical Examinations'!$A$1:$J$2336,8,FALSE) -> No | U1706: =VLOOKUP(A1706,'Medical Examinations'!$A$1:$J$2336,9,FALSE) -> Obesity | V1706: =VLOOKUP(A1706,'Medical Examinations'!$A$1:$J$2336,10,FALSE) -> Diabetes
A1707: Id630 | B1707: 1960 | C1707: Jun | D1707: 6 | E1707: =CONCATENATE(D1707," ",C1707," ",B1707) -> 6 Jun 1960 | F1707: =IF(M1707<=30,"20-30",IF(M1707<=40,"31-40",IF(M1707<=50,"41-50","51+"))) -> 51+ | G1707: 15612.19 | H1707: tier - 2 | I1707: tier - 2 | J1707: R1012 | L1707: =VLOOKUP(A1707,'Customer Names'!$A$2:$B$2336,2,FALSE) -> Phillips | M1707: =DATEDIF(E1707,$K$2,"y") -> 64 | N1707: =VLOOKUP(A1707,'Medical Examinations'!$A$2:$B$2336,2,FALSE) -> 32.965 | O1707: =VLOOKUP(A1707,'Medical Examinations'!$A$1:$J$2336,3,FALSE) -> 11.78 | P1707: =VLOOKUP(A1707,'Medical Examinations'!$A$1:$J$2336,4,FALSE) -> No | Q1707: =VLOOKUP(A1707,'Medical Examinations'!$A$1:$J$2336,5,FALSE) -> No | R1707: =VLOOKUP(A1707,'Medical Examinations'!$A$1:$J$2336,7,FALSE) -> 0 | S1707: =VLOOKUP(A1707,'Medical Examinations'!$A$1:$J$2336,6,FALSE) -> No | T1707: =VLOOKUP(A1708,'Medical Examinations'!$A$1:$J$2336,8,FALSE) -> No | U1707: =VLOOKUP(A1707,'Medical Examinations'!$A$1:$J$2336,9,FALSE) -> Obesity | V1707: =VLOOKUP(A1707,'Medical Examinations'!$A$1:$J$2336,10,FALSE) -> Diabetes
